Workbook

Sheet business_units
A1: bu_id | B1: bu_name | C1: primary_product | D1: target_hedge_ratio | E1: hedging_policy | F1: sanctioned_credit_line_inr
A2: BU01 | B2: Packaging Films | C2: Flexible packaging films | D2: 0.7 | E2: Hedge 60-80% of USD/EUR exports and crude-linked feedstock | F2: 1365200000
A3: BU02 | B3: Industrial Resins | C3: Commodity and industrial resins | D3: 0.2 | E3: Hedge 20% of crude-linked feedstock; exports left open | F3: 415500000
A4: BU03 | B4: Specialty Chemicals | C4: Specialty chemicals for export | D4: 0.5 | E4: Hedge about 50% of EUR/USD exports | F4: 490600000
A5: BU04 | B5: Consumer Plastics | C5: Domestic consumer plastics | D5: 0.5 | E5: Hedge about 50% of feedstock; mainly INR sales | F5: 617700000
A6: BU05 | B6: Engineering Compounds | C6: Engineering plastic compounds | D6: 0.35 | E6: Hedge 30-40% of feedstock and exports | F6: 423500000

Sheet treasury_monthly
A1: treasury_id | B1: bu_id | C1: month_end | D1: opening_cash | E1: cash_inflows | F1: cash_outflows | G1: net_borrowing | H1: inventory | I1: trade_receivables | J1: current_assets | K1: current_liabilities | L1: short_term_debt_due_30d | M1: undrawn_credit_line | N1: closing_cash
A2: TR0001 | B2: BU01 | C2: 45046 | D2: 182032291 | E2: 238643650 | F2: 170652359 | G2: -36066175 | H2: 84227738 | I2: 378518564 | J2: 676703709 | K2: 445917720 | L2: 288734020 | M2: 1279953499 | N2: 213957407
A3: TR0002 | B3: BU01 | C3: 45077 | D3: 213957407 | E3: 185489721 | F3: 161087598 | G3: 0 | H3: 231339937 | I3: 491629258 | J3: 961328725 | K3: 514388812 | L3: 288760805 | M3: 1279953499 | N3: 238359530
A4: TR0003 | B4: BU01 | C4: 45107 | D4: 238359530 | E4: 200846909 | F4: 284933671 | G4: 0 | H4: 215563578 | I4: 634911689 | J4: 1004748035 | K4: 434572250 | L4: 283318475 | M4: 1279953499 | N4: 154272768
A5: TR0004 | B5: BU01 | C5: 45138 | D5: 154272767 | E5: 360628017 | F5: 204497681 | G5: -58501607 | H5: 205132507 | I5: 542033922 | J5: 999067925 | K5: 466334652 | L5: 268045049 | M5: 1338455106 | N5: 251901496
A6: TR0005 | B6: BU01 | C6: 45169 | D6: 251901496 | E6: 274644386 | F6: 270867867 | G6: -26787079 | H6: 188177282 | I6: 538222910 | J6: 955291127 | K6: 443487246 | L6: 262533701 | M6: 1365242185 | N6: 228890936
A7: TR0006 | B7: BU01 | C7: 45199 | D7: 228890935 | E7: 271117290 | F7: 294679437 | G7: 0 | H7: 247800017 | I7: 664459943 | J7: 1117588747 | K7: 443487246 | L7: 270586020 | M7: 1365242185 | N7: 205328788
A8: TR0007 | B8: BU01 | C8: 45230 | D8: 205328788 | E8: 246902321 | F8: 269308254 | G8: 0 | H8: 335048380 | I8: 836023271 | J8: 1353994507 | K8: 528666336 | L8: 278172810 | M8: 1365242185 | N8: 182922855
A9: TR0008 | B9: BU01 | C9: 45260 | D9: 182922856 | E9: 462805637 | F9: 324941577 | G9: 0 | H9: 316793730 | I9: 815137342 | J9: 1452717989 | K9: 498479231 | L9: 251706801 | M9: 1365242185 | N9: 320786916
A10: TR0009 | B10: BU01 | C10: 45291 | D10: 320786916 | E10: 455156070 | F10: 346519095 | G10: 0 | H10: 312042736 | I10: 830479857 | J10: 1571946484 | K10: 515698065 | L10: 265310450 | M10: 1365242185 | N10: 429423891
A11: TR0010 | B11: BU01 | C11: 45322 | D11: 429423891 | E11: 240600243 | F11: 327635934 | G11: 0 | H11: 309616686 | I11: 835631745 | J11: 1487636632 | K11: 515698065 | L11: 308850927 | M11: 1365242185 | N11: 342388200
A12: TR0011 | B12: BU01 | C12: 45351 | D12: 342388200 | E12: 331910708 | F12: 336108391 | G12: 0 | H12: 304121503 | I12: 1049972322 | J12: 1692284343 | K12: 481283712 | L12: 270939498 | M12: 1365242185 | N12: 338190517
A13: TR0012 | B13: BU01 | C13: 45382 | D13: 338190517 | E13: 344175936 | F13: 383157775 | G13: 0 | H13: 282207782 | I13: 1215148322 | J13: 1796564782 | K13: 629308980 | L13: 395728390 | M13: 1365242185 | N13: 299208678
... A120: TR0120 | B120: BU05 | C120: 45747 | D120: 217377521 | E120: 129668482 | F120: 142420879 | G120: 0 | H120: 168193379 | I120: 382008188 | J120: 754826690 | K120: 212376416 | L120: 97090778 | M120: 423452545 | N120: 204625124

Sheet invoices
A1: invoice_id | B1: customer_id | C1: bu_id | D1: invoice_date | E1: due_date | F1: currency | G1: invoice_amount | H1: paid_date | I1: status | J1: hedged_flag | K1: hedge_rate | L1: amount_paid | M1: fx_rate_inv | N1: invoice_amount_inr | O1: open_balance_inr | P1: days_overdue | Q1: days_late | R1: aging
A2: INV002586 | B2: C0019 | C2: BU05 | D2: 45721 | E2: 45811 | F2: EUR | G2: 497215.46 | I2: OPEN | J2: N | L2: 0 | M2: =IF(F2="INR",1,INDEX('rates'!$B$2:$C$522,MATCH(D2,'rates'!$A$2:$A$522,1),MATCH(F2&"/INR",'rates'!$B$1:$C$1,0))) -> 93.6278 | N2: =G2*M2 -> 46553190 | O2: =IF(OR(I2="OPEN",I2="PARTIALLY PAID"),(G2-L2)*M2,0) -> 46553190 | P2: =IF(O2>0,MAX(0,DATE(2025,3,31)-E2),0) -> 0 | Q2: =IF(H2="","",H2-E2) | R2: =IF(O2=0,"Not open",IF(P2=0,"Not yet due",IF(P2<=30,"1-30",IF(P2<=60,"31-60",IF(P2<=90,"61-90","90+"))))) -> Not yet due
A3: INV002659 | B3: C0049 | C3: BU01 | D3: 45738 | E3: 45768 | F3: INR | G3: 44151066 | I3: OPEN | J3: N | L3: 0 | M3: =IF(F3="INR",1,INDEX('rates'!$B$2:$C$522,MATCH(D3,'rates'!$A$2:$A$522,1),MATCH(F3&"/INR",'rates'!$B$1:$C$1,0))) -> 1 | N3: =G3*M3 -> 44151066 | O3: =IF(OR(I3="OPEN",I3="PARTIALLY PAID"),(G3-L3)*M3,0) -> 44151066 | P3: =IF(O3>0,MAX(0,DATE(2025,3,31)-E3),0) -> 0 | Q3: =IF(H3="","",H3-E3) | R3: =IF(O3=0,"Not open",IF(P3=0,"Not yet due",IF(P3<=30,"1-30",IF(P3<=60,"31-60",IF(P3<=90,"61-90","90+"))))) -> Not yet due
A4: INV002380 | B4: C0161 | C4: BU03 | D4: 45667 | E4: 45757 | F4: USD | G4: 431946.95 | I4: OPEN | J4: N | L4: 0 | M4: =IF(F4="INR",1,INDEX('rates'!$B$2:$C$522,MATCH(D4,'rates'!$A$2:$A$522,1),MATCH(F4&"/INR",'rates'!$B$1:$C$1,0))) -> 85.96 | N4: =G4*M4 -> 37130160 | O4: =IF(OR(I4="OPEN",I4="PARTIALLY PAID"),(G4-L4)*M4,0) -> 37130160 | P4: =IF(O4>0,MAX(0,DATE(2025,3,31)-E4),0) -> 0 | Q4: =IF(H4="","",H4-E4) | R4: =IF(O4=0,"Not open",IF(P4=0,"Not yet due",IF(P4<=30,"1-30",IF(P4<=60,"31-60",IF(P4<=90,"61-90","90+"))))) -> Not yet due
A5: INV002609 | B5: C0039 | C5: BU04 | D5: 45727 | E5: 45787 | F5: INR | G5: 36730540 | I5: OPEN | J5: N | L5: 0 | M5: =IF(F5="INR",1,INDEX('rates'!$B$2:$C$522,MATCH(D5,'rates'!$A$2:$A$522,1),MATCH(F5&"/INR",'rates'!$B$1:$C$1,0))) -> 1 | N5: =G5*M5 -> 36730540 | O5: =IF(OR(I5="OPEN",I5="PARTIALLY PAID"),(G5-L5)*M5,0) -> 36730540 | P5: =IF(O5>0,MAX(0,DATE(2025,3,31)-E5),0) -> 0 | Q5: =IF(H5="","",H5-E5) | R5: =IF(O5=0,"Not open",IF(P5=0,"Not yet due",IF(P5<=30,"1-30",IF(P5<=60,"31-60",IF(P5<=90,"61-90","90+"))))) -> Not yet due
A6: INV002371 | B6: C0111 | C6: BU01 | D6: 45666 | E6: 45756 | F6: EUR | G6: 358641.79 | I6: OPEN | J6: Y | K6: 88.6942 | L6: 0 | M6: =IF(F6="INR",1,INDEX('rates'!$B$2:$C$522,MATCH(D6,'rates'!$A$2:$A$522,1),MATCH(F6&"/INR",'rates'!$B$1:$C$1,0))) -> 88.4289 | N6: =G6*M6 -> 31714299 | O6: =IF(OR(I6="OPEN",I6="PARTIALLY PAID"),(G6-L6)*M6,0) -> 31714299 | P6: =IF(O6>0,MAX(0,DATE(2025,3,31)-E6),0) -> 0 | Q6: =IF(H6="","",H6-E6) | R6: =IF(O6=0,"Not open",IF(P6=0,"Not yet due",IF(P6<=30,"1-30",IF(P6<=60,"31-60",IF(P6<=90,"61-90","90+"))))) -> Not yet due
A7: INV002617 | B7: C0138 | C7: BU03 | D7: 45728 | E7: 45758 | F7: INR | G7: 30751759 | I7: OPEN | J7: N | L7: 0 | M7: =IF(F7="INR",1,INDEX('rates'!$B$2:$C$522,MATCH(D7,'rates'!$A$2:$A$522,1),MATCH(F7&"/INR",'rates'!$B$1:$C$1,0))) -> 1 | N7: =G7*M7 -> 30751759 | O7: =IF(OR(I7="OPEN",I7="PARTIALLY PAID"),(G7-L7)*M7,0) -> 30751759 | P7: =IF(O7>0,MAX(0,DATE(2025,3,31)-E7),0) -> 0 | Q7: =IF(H7="","",H7-E7) | R7: =IF(O7=0,"Not open",IF(P7=0,"Not yet due",IF(P7<=30,"1-30",IF(P7<=60,"31-60",IF(P7<=90,"61-90","90+"))))) -> Not yet due
A8: INV002511 | B8: C0166 | C8: BU05 | D8: 45701 | E8: 45791 | F8: INR | G8: 29692974 | I8: OPEN | J8: N | L8: 0 | M8: =IF(F8="INR",1,INDEX('rates'!$B$2:$C$522,MATCH(D8,'rates'!$A$2:$A$522,1),MATCH(F8&"/INR",'rates'!$B$1:$C$1,0))) -> 1 | N8: =G8*M8 -> 29692974 | O8: =IF(OR(I8="OPEN",I8="PARTIALLY PAID"),(G8-L8)*M8,0) -> 29692974 | P8: =IF(O8>0,MAX(0,DATE(2025,3,31)-E8),0) -> 0 | Q8: =IF(H8="","",H8-E8) | R8: =IF(O8=0,"Not open",IF(P8=0,"Not yet due",IF(P8<=30,"1-30",IF(P8<=60,"31-60",IF(P8<=90,"61-90","90+"))))) -> Not yet due
A9: INV002628 | B9: C0029 | C9: BU02 | D9: 45731 | E9: 45821 | F9: INR | G9: 28920720 | I9: OPEN | J9: N | L9: 0 | M9: =IF(F9="INR",1,INDEX('rates'!$B$2:$C$522,MATCH(D9,'rates'!$A$2:$A$522,1),MATCH(F9&"/INR",'rates'!$B$1:$C$1,0))) -> 1 | N9: =G9*M9 -> 28920720 | O9: =IF(OR(I9="OPEN",I9="PARTIALLY PAID"),(G9-L9)*M9,0) -> 28920720 | P9: =IF(O9>0,MAX(0,DATE(2025,3,31)-E9),0) -> 0 | Q9: =IF(H9="","",H9-E9) | R9: =IF(O9=0,"Not open",IF(P9=0,"Not yet due",IF(P9<=30,"1-30",IF(P9<=60,"31-60",IF(P9<=90,"61-90","90+"))))) -> Not yet due
A10: INV002585 | B10: C0211 | C10: BU01 | D10: 45720 | E10: 45765 | F10: INR | G10: 27466762 | I10: OPEN | J10: N | L10: 0 | M10: =IF(F10="INR",1,INDEX('rates'!$B$2:$C$522,MATCH(D10,'rates'!$A$2:$A$522,1),MATCH(F10&"/INR",'rates'!$B$1:$C$1,0))) -> 1 | N10: =G10*M10 -> 27466762 | O10: =IF(OR(I10="OPEN",I10="PARTIALLY PAID"),(G10-L10)*M10,0) -> 27466762 | P10: =IF(O10>0,MAX(0,DATE(2025,3,31)-E10),0) -> 0 | Q10: =IF(H10="","",H10-E10) | R10: =IF(O10=0,"Not open",IF(P10=0,"Not yet due",IF(P10<=30,"1-30",IF(P10<=60,"31-60",IF(P10<=90,"61-90","90+"))))) -> Not yet due
A11: INV002557 | B11: C0224 | C11: BU02 | D11: 45710 | E11: 45740 | F11: EUR | G11: 291923.04 | I11: OPEN | J11: N | L11: 0 | M11: =IF(F11="INR",1,INDEX('rates'!$B$2:$C$522,MATCH(D11,'rates'!$A$2:$A$522,1),MATCH(F11&"/INR",'rates'!$B$1:$C$1,0))) -> 90.6448 | N11: =G11*M11 -> 26461306 | O11: =IF(OR(I11="OPEN",I11="PARTIALLY PAID"),(G11-L11)*M11,0) -> 26461306 | P11: =IF(O11>0,MAX(0,DATE(2025,3,31)-E11),0) -> 7 | Q11: =IF(H11="","",H11-E11) | R11: =IF(O11=0,"Not open",IF(P11=0,"Not yet due",IF(P11<=30,"1-30",IF(P11<=60,"31-60",IF(P11<=90,"61-90","90+"))))) -> 1-30
A12: INV002572 | B12: C0146 | C12: BU01 | D12: 45717 | E12: 45777 | F12: USD | G12: 289490.53 | I12: OPEN | J12: Y | K12: 87.7917 | L12: 0 | M12: =IF(F12="INR",1,INDEX('rates'!$B$2:$C$522,MATCH(D12,'rates'!$A$2:$A$522,1),MATCH(F12&"/INR",'rates'!$B$1:$C$1,0))) -> 87.5 | N12: =G12*M12 -> 25330421 | O12: =IF(OR(I12="OPEN",I12="PARTIALLY PAID"),(G12-L12)*M12,0) -> 25330421 | P12: =IF(O12>0,MAX(0,DATE(2025,3,31)-E12),0) -> 0 | Q12: =IF(H12="","",H12-E12) | R12: =IF(O12=0,"Not open",IF(P12=0,"Not yet due",IF(P12<=30,"1-30",IF(P12<=60,"31-60",IF(P12<=90,"61-90","90+"))))) -> Not yet due
A13: INV002336 | B13: C0153 | C13: BU03 | D13: 45658 | E13: 45748 | F13: INR | G13: 24438240 | I13: OPEN | J13: N | L13: 0 | M13: =IF(F13="INR",1,INDEX('rates'!$B$2:$C$522,MATCH(D13,'rates'!$A$2:$A$522,1),MATCH(F13&"/INR",'rates'!$B$1:$C$1,0))) -> 1 | N13: =G13*M13 -> 24438240 | O13: =IF(OR(I13="OPEN",I13="PARTIALLY PAID"),(G13-L13)*M13,0) -> 24438240 | P13: =IF(O13>0,MAX(0,DATE(2025,3,31)-E13),0) -> 0 | Q13: =IF(H13="","",H13-E13) | R13: =IF(O13=0,"Not open",IF(P13=0,"Not yet due",IF(P13<=30,"1-30",IF(P13<=60,"31-60",IF(P13<=90,"61-90","90+"))))) -> Not yet due
A14: INV002644 | B14: C0005 | C14: BU05 | D14: 45734 | E14: 45764 | F14: INR | G14: 24397292 | I14: OPEN | J14: N | L14: 0 | M14: =IF(F14="INR",1,INDEX('rates'!$B$2:$C$522,MATCH(D14,'rates'!$A$2:$A$522,1),MATCH(F14&"/INR",'rates'!$B$1:$C$1,0))) -> 1 | N14: =G14*M14 -> 24397292 | O14: =IF(OR(I14="OPEN",I14="PARTIALLY PAID"),(G14-L14)*M14,0) -> 24397292 | P14: =IF(O14>0,MAX(0,DATE(2025,3,31)-E14),0) -> 0 | Q14: =IF(H14="","",H14-E14) | R14: =IF(O14=0,"Not open",IF(P14=0,"Not yet due",IF(P14<=30,"1-30",IF(P14<=60,"31-60",IF(P14<=90,"61-90","90+"))))) -> Not yet due
A15: INV002365 | B15: C0212 | C15: BU05 | D15: 45665 | E15: 45755 | F15: INR | G15: 24031583 | I15: OPEN | J15: N | L15: 0 | M15: =IF(F15="INR",1,INDEX('rates'!$B$2:$C$522,MATCH(D15,'rates'!$A$2:$A$522,1),MATCH(F15&"/INR",'rates'!$B$1:$C$1,0))) -> 1 | N15: =G15*M15 -> 24031583 | O15: =IF(OR(I15="OPEN",I15="PARTIALLY PAID"),(G15-L15)*M15,0) -> 24031583 | P15: =IF(O15>0,MAX(0,DATE(2025,3,31)-E15),0) -> 0 | Q15: =IF(H15="","",H15-E15) | R15: =IF(O15=0,"Not open",IF(P15=0,"Not yet due",IF(P15<=30,"1-30",IF(P15<=60,"31-60",IF(P15<=90,"61-90","90+"))))) -> Not yet due
A16: INV002627 | B16: C0236 | C16: BU01 | D16: 45730 | E16: 45790 | F16: EUR | G16: 250227.09 | I16: OPEN | J16: Y | K16: 94.7756 | L16: 0 | M16: =IF(F16="INR",1,INDEX('rates'!$B$2:$C$522,MATCH(D16,'rates'!$A$2:$A$522,1),MATCH(F16&"/INR",'rates'!$B$1:$C$1,0))) -> 94.5864 | N16: =G16*M16 -> 23668080 | O16: =IF(OR(I16="OPEN",I16="PARTIALLY PAID"),(G16-L16)*M16,0) -> 23668080 | P16: =IF(O16>0,MAX(0,DATE(2025,3,31)-E16),0) -> 0 | Q16: =IF(H16="","",H16-E16) | R16: =IF(O16=0,"Not open",IF(P16=0,"Not yet due",IF(P16<=30,"1-30",IF(P16<=60,"31-60",IF(P16<=90,"61-90","90+"))))) -> Not yet due
A17: INV002509 | B17: C0141 | C17: BU01 | D17: 45701 | E17: 45761 | F17: INR | G17: 23523276 | I17: OPEN | J17: N | L17: 0 | M17: =IF(F17="INR",1,INDEX('rates'!$B$2:$C$522,MATCH(D17,'rates'!$A$2:$A$522,1),MATCH(F17&"/INR",'rates'!$B$1:$C$1,0))) -> 1 | N17: =G17*M17 -> 23523276 | O17: =IF(OR(I17="OPEN",I17="PARTIALLY PAID"),(G17-L17)*M17,0) -> 23523276 | P17: =IF(O17>0,MAX(0,DATE(2025,3,31)-E17),0) -> 0 | Q17: =IF(H17="","",H17-E17) | R17: =IF(O17=0,"Not open",IF(P17=0,"Not yet due",IF(P17<=30,"1-30",IF(P17<=60,"31-60",IF(P17<=90,"61-90","90+"))))) -> Not yet due
A18: INV002615 | B18: C0198 | C18: BU01 | D18: 45727 | E18: 45772 | F18: USD | G18: 266232.61 | I18: OPEN | J18: Y | K18: 87.3779 | L18: 0 | M18: =IF(F18="INR",1,INDEX('rates'!$B$2:$C$522,MATCH(D18,'rates'!$A$2:$A$522,1),MATCH(F18&"/INR",'rates'!$B$1:$C$1,0))) -> 87.16 | N18: =G18*M18 -> 23204834 | O18: =IF(OR(I18="OPEN",I18="PARTIALLY PAID"),(G18-L18)*M18,0) -> 23204834 | P18: =IF(O18>0,MAX(0,DATE(2025,3,31)-E18),0) -> 0 | Q18: =IF(H18="","",H18-E18) | R18: =IF(O18=0,"Not open",IF(P18=0,"Not yet due",IF(P18<=30,"1-30",IF(P18<=60,"31-60",IF(P18<=90,"61-90","90+"))))) -> Not yet due
A19: INV002447 | B19: C0198 | C19: BU01 | D19: 45684 | E19: 45729 | F19: USD | G19: 262232.01 | I19: OPEN | J19: Y | K19: 86.5558 | L19: 0 | M19: =IF(F19="INR",1,INDEX('rates'!$B$2:$C$522,MATCH(D19,'rates'!$A$2:$A$522,1),MATCH(F19&"/INR",'rates'!$B$1:$C$1,0))) -> 86.34 | N19: =G19*M19 -> 22641112 | O19: =IF(OR(I19="OPEN",I19="PARTIALLY PAID"),(G19-L19)*M19,0) -> 22641112 | P19: =IF(O19>0,MAX(0,DATE(2025,3,31)-E19),0) -> 18 | Q19: =IF(H19="","",H19-E19) | R19: =IF(O19=0,"Not open",IF(P19=0,"Not yet due",IF(P19<=30,"1-30",IF(P19<=60,"31-60",IF(P19<=90,"61-90","90+"))))) -> 1-30
A20: INV002355 | B20: C0236 | C20: BU02 | D20: 45661 | E20: 45721 | F20: EUR | G20: 242682.17 | I20: OPEN | J20: N | L20: 0 | M20: =IF(F20="INR",1,INDEX('rates'!$B$2:$C$522,MATCH(D20,'rates'!$A$2:$A$522,1),MATCH(F20&"/INR",'rates'!$B$1:$C$1,0))) -> 88.2539 | N20: =G20*M20 -> 21417648 | O20: =IF(OR(I20="OPEN",I20="PARTIALLY PAID"),(G20-L20)*M20,0) -> 21417648 | P20: =IF(O20>0,MAX(0,DATE(2025,3,31)-E20),0) -> 26 | Q20: =IF(H20="","",H20-E20) | R20: =IF(O20=0,"Not open",IF(P20=0,"Not yet due",IF(P20<=30,"1-30",IF(P20<=60,"31-60",IF(P20<=90,"61-90","90+"))))) -> 1-30
A21: INV002346 | B21: C0236 | C21: BU01 | D21: 45659 | E21: 45719 | F21: EUR | G21: 236219.66 | I21: OPEN | J21: Y | K21: 88.1641 | L21: 0 | M21: =IF(F21="INR",1,INDEX('rates'!$B$2:$C$522,MATCH(D21,'rates'!$A$2:$A$522,1),MATCH(F21&"/INR",'rates'!$B$1:$C$1,0))) -> 87.9881 | N21: =G21*M21 -> 20784519 | O21: =IF(OR(I21="OPEN",I21="PARTIALLY PAID"),(G21-L21)*M21,0) -> 20784519 | P21: =IF(O21>0,MAX(0,DATE(2025,3,31)-E21),0) -> 28 | Q21: =IF(H21="","",H21-E21) | R21: =IF(O21=0,"Not open",IF(P21=0,"Not yet due",IF(P21<=30,"1-30",IF(P21<=60,"31-60",IF(P21<=90,"61-90","90+"))))) -> 1-30
A22: INV002601 | B22: C0060 | C22: BU02 | D22: 45724 | E22: 45769 | F22: INR | G22: 20457785 | I22: OPEN | J22: N | L22: 0 | M22: =IF(F22="INR",1,INDEX('rates'!$B$2:$C$522,MATCH(D22,'rates'!$A$2:$A$522,1),MATCH(F22&"/INR",'rates'!$B$1:$C$1,0))) -> 1 | N22: =G22*M22 -> 20457785 | O22: =IF(OR(I22="OPEN",I22="PARTIALLY PAID"),(G22-L22)*M22,0) -> 20457785 | P22: =IF(O22>0,MAX(0,DATE(2025,3,31)-E22),0) -> 0 | Q22: =IF(H22="","",H22-E22) | R22: =IF(O22=0,"Not open",IF(P22=0,"Not yet due",IF(P22<=30,"1-30",IF(P22<=60,"31-60",IF(P22<=90,"61-90","90+"))))) -> Not yet due
A23: INV002555 | B23: C0111 | C23: BU01 | D23: 45710 | E23: 45800 | F23: EUR | G23: 218730.33 | I23: OPEN | J23: Y | K23: 90.9167 | L23: 0 | M23: =IF(F23="INR",1,INDEX('rates'!$B$2:$C$522,MATCH(D23,'rates'!$A$2:$A$522,1),MATCH(F23&"/INR",'rates'!$B$1:$C$1,0))) -> 90.6448 | N23: =G23*M23 -> 19826767 | O23: =IF(OR(I23="OPEN",I23="PARTIALLY PAID"),(G23-L23)*M23,0) -> 19826767 | P23: =IF(O23>0,MAX(0,DATE(2025,3,31)-E23),0) -> 0 | Q23: =IF(H23="","",H23-E23) | R23: =IF(O23=0,"Not open",IF(P23=0,"Not yet due",IF(P23<=30,"1-30",IF(P23<=60,"31-60",IF(P23<=90,"61-90","90+"))))) -> Not yet due
A24: INV001815 | B24: C0140 | C24: BU03 | D24: 45528 | E24: 45573 | F24: INR | G24: 19790384 | I24: OPEN | J24: N | L24: 0 | M24: =IF(F24="INR",1,INDEX('rates'!$B$2:$C$522,MATCH(D24,'rates'!$A$2:$A$522,1),MATCH(F24&"/INR",'rates'!$B$1:$C$1,0))) -> 1 | N24: =G24*M24 -> 19790384 | O24: =IF(OR(I24="OPEN",I24="PARTIALLY PAID"),(G24-L24)*M24,0) -> 19790384 | P24: =IF(O24>0,MAX(0,DATE(2025,3,31)-E24),0) -> 174 | Q24: =IF(H24="","",H24-E24) | R24: =IF(O24=0,"Not open",IF(P24=0,"Not yet due",IF(P24<=30,"1-30",IF(P24<=60,"31-60",IF(P24<=90,"61-90","90+"))))) -> 90+
A25: INV002403 | B25: C0166 | C25: BU03 | D25: 45672 | E25: 45762 | F25: INR | G25: 19644052 | I25: OPEN | J25: N | L25: 0 | M25: =IF(F25="INR",1,INDEX('rates'!$B$2:$C$522,MATCH(D25,'rates'!$A$2:$A$522,1),MATCH(F25&"/INR",'rates'!$B$1:$C$1,0))) -> 1 | N25: =G25*M25 -> 19644052 | O25: =IF(OR(I25="OPEN",I25="PARTIALLY PAID"),(G25-L25)*M25,0) -> 19644052 | P25: =IF(O25>0,MAX(0,DATE(2025,3,31)-E25),0) -> 0 | Q25: =IF(H25="","",H25-E25) | R25: =IF(O25=0,"Not open",IF(P25=0,"Not yet due",IF(P25<=30,"1-30",IF(P25<=60,"31-60",IF(P25<=90,"61-90","90+"))))) -> Not yet due
A26: INV001991 | B26: C0180 | C26: BU02 | D26: 45572 | E26: 45617 | F26: USD | G26: 233241.23 | I26: OPEN | J26: N | L26: 0 | M26: =IF(F26="INR",1,INDEX('rates'!$B$2:$C$522,MATCH(D26,'rates'!$A$2:$A$522,1),MATCH(F26&"/INR",'rates'!$B$1:$C$1,0))) -> 83.96 | N26: =G26*M26 -> 19582934 | O26: =IF(OR(I26="OPEN",I26="PARTIALLY PAID"),(G26-L26)*M26,0) -> 19582934 | P26: =IF(O26>0,MAX(0,DATE(2025,3,31)-E26),0) -> 130 | Q26: =IF(H26="","",H26-E26) | R26: =IF(O26=0,"Not open",IF(P26=0,"Not yet due",IF(P26<=30,"1-30",IF(P26<=60,"31-60",IF(P26<=90,"61-90","90+"))))) -> 90+
A27: INV002669 | B27: C0029 | C27: BU02 | D27: 45740 | E27: 45830 | F27: INR | G27: 19264703 | I27: OPEN | J27: N | L27: 0 | M27: =IF(F27="INR",1,INDEX('rates'!$B$2:$C$522,MATCH(D27,'rates'!$A$2:$A$522,1),MATCH(F27&"/INR",'rates'!$B$1:$C$1,0))) -> 1 | N27: =G27*M27 -> 19264703 | O27: =IF(OR(I27="OPEN",I27="PARTIALLY PAID"),(G27-L27)*M27,0) -> 19264703 | P27: =IF(O27>0,MAX(0,DATE(2025,3,31)-E27),0) -> 0 | Q27: =IF(H27="","",H27-E27) | R27: =IF(O27=0,"Not open",IF(P27=0,"Not yet due",IF(P27<=30,"1-30",IF(P27<=60,"31-60",IF(P27<=90,"61-90","90+"))))) -> Not yet due
A28: INV002544 | B28: C0228 | C28: BU04 | D28: 45707 | E28: 45752 | F28: INR | G28: 19154675 | I28: OPEN | J28: N | L28: 0 | M28: =IF(F28="INR",1,INDEX('rates'!$B$2:$C$522,MATCH(D28,'rates'!$A$2:$A$522,1),MATCH(F28&"/INR",'rates'!$B$1:$C$1,0))) -> 1 | N28: =G28*M28 -> 19154675 | O28: =IF(OR(I28="OPEN",I28="PARTIALLY PAID"),(G28-L28)*M28,0) -> 19154675 | P28: =IF(O28>0,MAX(0,DATE(2025,3,31)-E28),0) -> 0 | Q28: =IF(H28="","",H28-E28) | R28: =IF(O28=0,"Not open",IF(P28=0,"Not yet due",IF(P28<=30,"1-30",IF(P28<=60,"31-60",IF(P28<=90,"61-90","90+"))))) -> Not yet due
A29: INV002265 | B29: C0198 | C29: BU01 | D29: 45638 | E29: 45683 | F29: USD | G29: 225595.07 | I29: OPEN | J29: Y | K29: 85.0521 | L29: 0 | M29: =IF(F29="INR",1,INDEX('rates'!$B$2:$C$522,MATCH(D29,'rates'!$A$2:$A$522,1),MATCH(F29&"/INR",'rates'!$B$1:$C$1,0))) -> 84.84 | N29: =G29*M29 -> 19139486 | O29: =IF(OR(I29="OPEN",I29="PARTIALLY PAID"),(G29-L29)*M29,0) -> 19139486 | P29: =IF(O29>0,MAX(0,DATE(2025,3,31)-E29),0) -> 64 | Q29: =IF(H29="","",H29-E29) | R29: =IF(O29=0,"Not open",IF(P29=0,"Not yet due",IF(P29<=30,"1-30",IF(P29<=60,"31-60",IF(P29<=90,"61-90","90+"))))) -> 61-90
A30: INV002474 | B30: C0071 | C30: BU02 | D30: 45693 | E30: 45753 | F30: USD | G30: 217524.13 | I30: OPEN | J30: N | L30: 0 | M30: =IF(F30="INR",1,INDEX('rates'!$B$2:$C$522,MATCH(D30,'rates'!$A$2:$A$522,1),MATCH(F30&"/INR",'rates'!$B$1:$C$1,0))) -> 87.08 | N30: =G30*M30 -> 18942001 | O30: =IF(OR(I30="OPEN",I30="PARTIALLY PAID"),(G30-L30)*M30,0) -> 18942001 | P30: =IF(O30>0,MAX(0,DATE(2025,3,31)-E30),0) -> 0 | Q30: =IF(H30="","",H30-E30) | R30: =IF(O30=0,"Not open",IF(P30=0,"Not yet due",IF(P30<=30,"1-30",IF(P30<=60,"31-60",IF(P30<=90,"61-90","90+"))))) -> Not yet due
A31: INV002658 | B31: C0049 | C31: BU01 | D31: 45738 | E31: 45768 | F31: INR | G31: 18886440 | I31: OPEN | J31: N | L31: 0 | M31: =IF(F31="INR",1,INDEX('rates'!$B$2:$C$522,MATCH(D31,'rates'!$A$2:$A$522,1),MATCH(F31&"/INR",'rates'!$B$1:$C$1,0))) -> 1 | N31: =G31*M31 -> 18886440 | O31: =IF(OR(I31="OPEN",I31="PARTIALLY PAID"),(G31-L31)*M31,0) -> 18886440 | P31: =IF(O31>0,MAX(0,DATE(2025,3,31)-E31),0) -> 0 | Q31: =IF(H31="","",H31-E31) | R31: =IF(O31=0,"Not open",IF(P31=0,"Not yet due",IF(P31<=30,"1-30",IF(P31<=60,"31-60",IF(P31<=90,"61-90","90+"))))) -> Not yet due
A32: INV002531 | B32: C0238 | C32: BU05 | D32: 45703 | E32: 45763 | F32: INR | G32: 18690785 | I32: OPEN | J32: N | L32: 0 | M32: =IF(F32="INR",1,INDEX('rates'!$B$2:$C$522,MATCH(D32,'rates'!$A$2:$A$522,1),MATCH(F32&"/INR",'rates'!$B$1:$C$1,0))) -> 1 | N32: =G32*M32 -> 18690785 | O32: =IF(OR(I32="OPEN",I32="PARTIALLY PAID"),(G32-L32)*M32,0) -> 18690785 | P32: =IF(O32>0,MAX(0,DATE(2025,3,31)-E32),0) -> 0 | Q32: =IF(H32="","",H32-E32) | R32: =IF(O32=0,"Not open",IF(P32=0,"Not yet due",IF(P32<=30,"1-30",IF(P32<=60,"31-60",IF(P32<=90,"61-90","90+"))))) -> Not yet due
A33: INV002419 | B33: C0056 | C33: BU02 | D33: 45678 | E33: 45738 | F33: INR | G33: 18481351 | I33: OPEN | J33: N | L33: 0 | M33: =IF(F33="INR",1,INDEX('rates'!$B$2:$C$522,MATCH(D33,'rates'!$A$2:$A$522,1),MATCH(F33&"/INR",'rates'!$B$1:$C$1,0))) -> 1 | N33: =G33*M33 -> 18481351 | O33: =IF(OR(I33="OPEN",I33="PARTIALLY PAID"),(G33-L33)*M33,0) -> 18481351 | P33: =IF(O33>0,MAX(0,DATE(2025,3,31)-E33),0) -> 9 | Q33: =IF(H33="","",H33-E33) | R33: =IF(O33=0,"Not open",IF(P33=0,"Not yet due",IF(P33<=30,"1-30",IF(P33<=60,"31-60",IF(P33<=90,"61-90","90+"))))) -> 1-30
A34: INV002482 | B34: C0103 | C34: BU04 | D34: 45694 | E34: 45754 | F34: INR | G34: 18249855 | I34: OPEN | J34: N | L34: 0 | M34: =IF(F34="INR",1,INDEX('rates'!$B$2:$C$522,MATCH(D34,'rates'!$A$2:$A$522,1),MATCH(F34&"/INR",'rates'!$B$1:$C$1,0))) -> 1 | N34: =G34*M34 -> 18249855 | O34: =IF(OR(I34="OPEN",I34="PARTIALLY PAID"),(G34-L34)*M34,0) -> 18249855 | P34: =IF(O34>0,MAX(0,DATE(2025,3,31)-E34),0) -> 0 | Q34: =IF(H34="","",H34-E34) | R34: =IF(O34=0,"Not open",IF(P34=0,"Not yet due",IF(P34<=30,"1-30",IF(P34<=60,"31-60",IF(P34<=90,"61-90","90+"))))) -> Not yet due
A35: INV002663 | B35: C0138 | C35: BU03 | D35: 45738 | E35: 45768 | F35: INR | G35: 18108442 | I35: OPEN | J35: N | L35: 0 | M35: =IF(F35="INR",1,INDEX('rates'!$B$2:$C$522,MATCH(D35,'rates'!$A$2:$A$522,1),MATCH(F35&"/INR",'rates'!$B$1:$C$1,0))) -> 1 | N35: =G35*M35 -> 18108442 | O35: =IF(OR(I35="OPEN",I35="PARTIALLY PAID"),(G35-L35)*M35,0) -> 18108442 | P35: =IF(O35>0,MAX(0,DATE(2025,3,31)-E35),0) -> 0 | Q35: =IF(H35="","",H35-E35) | R35: =IF(O35=0,"Not open",IF(P35=0,"Not yet due",IF(P35<=30,"1-30",IF(P35<=60,"31-60",IF(P35<=90,"61-90","90+"))))) -> Not yet due
A36: INV002607 | B36: C0039 | C36: BU04 | D36: 45726 | E36: 45786 | F36: INR | G36: 17905495 | I36: OPEN | J36: N | L36: 0 | M36: =IF(F36="INR",1,INDEX('rates'!$B$2:$C$522,MATCH(D36,'rates'!$A$2:$A$522,1),MATCH(F36&"/INR",'rates'!$B$1:$C$1,0))) -> 1 | N36: =G36*M36 -> 17905495 | O36: =IF(OR(I36="OPEN",I36="PARTIALLY PAID"),(G36-L36)*M36,0) -> 17905495 | P36: =IF(O36>0,MAX(0,DATE(2025,3,31)-E36),0) -> 0 | Q36: =IF(H36="","",H36-E36) | R36: =IF(O36=0,"Not open",IF(P36=0,"Not yet due",IF(P36<=30,"1-30",IF(P36<=60,"31-60",IF(P36<=90,"61-90","90+"))))) -> Not yet due
A37: INV002687 | B37: C0061 | C37: BU02 | D37: 45744 | E37: 45834 | F37: INR | G37: 17390108 | I37: OPEN | J37: N | L37: 0 | M37: =IF(F37="INR",1,INDEX('rates'!$B$2:$C$522,MATCH(D37,'rates'!$A$2:$A$522,1),MATCH(F37&"/INR",'rates'!$B$1:$C$1,0))) -> 1 | N37: =G37*M37 -> 17390108 | O37: =IF(OR(I37="OPEN",I37="PARTIALLY PAID"),(G37-L37)*M37,0) -> 17390108 | P37: =IF(O37>0,MAX(0,DATE(2025,3,31)-E37),0) -> 0 | Q37: =IF(H37="","",H37-E37) | R37: =IF(O37=0,"Not open",IF(P37=0,"Not yet due",IF(P37<=30,"1-30",IF(P37<=60,"31-60",IF(P37<=90,"61-90","90+"))))) -> Not yet due
A38: INV002504 | B38: C0146 | C38: BU01 | D38: 45700 | E38: 45760 | F38: USD | G38: 199230.33 | I38: OPEN | J38: Y | K38: 87.1897 | L38: 0 | M38: =IF(F38="INR",1,INDEX('rates'!$B$2:$C$522,MATCH(D38,'rates'!$A$2:$A$522,1),MATCH(F38&"/INR",'rates'!$B$1:$C$1,0))) -> 86.9 | N38: =G38*M38 -> 17313116 | O38: =IF(OR(I38="OPEN",I38="PARTIALLY PAID"),(G38-L38)*M38,0) -> 17313116 | P38: =IF(O38>0,MAX(0,DATE(2025,3,31)-E38),0) -> 0 | Q38: =IF(H38="","",H38-E38) | R38: =IF(O38=0,"Not open",IF(P38=0,"Not yet due",IF(P38<=30,"1-30",IF(P38<=60,"31-60",IF(P38<=90,"61-90","90+"))))) -> Not yet due
A39: INV002471 | B39: C0166 | C39: BU05 | D39: 45692 | E39: 45782 | F39: INR | G39: 16989427 | I39: OPEN | J39: N | L39: 0 | M39: =IF(F39="INR",1,INDEX('rates'!$B$2:$C$522,MATCH(D39,'rates'!$A$2:$A$522,1),MATCH(F39&"/INR",'rates'!$B$1:$C$1,0))) -> 1 | N39: =G39*M39 -> 16989427 | O39: =IF(OR(I39="OPEN",I39="PARTIALLY PAID"),(G39-L39)*M39,0) -> 16989427 | P39: =IF(O39>0,MAX(0,DATE(2025,3,31)-E39),0) -> 0 | Q39: =IF(H39="","",H39-E39) | R39: =IF(O39=0,"Not open",IF(P39=0,"Not yet due",IF(P39<=30,"1-30",IF(P39<=60,"31-60",IF(P39<=90,"61-90","90+"))))) -> Not yet due
A40: INV002518 | B40: C0102 | C40: BU03 | D40: 45702 | E40: 45762 | F40: USD | G40: 186557.27 | I40: OPEN | J40: N | L40: 0 | M40: =IF(F40="INR",1,INDEX('rates'!$B$2:$C$522,MATCH(D40,'rates'!$A$2:$A$522,1),MATCH(F40&"/INR",'rates'!$B$1:$C$1,0))) -> 86.82 | N40: =G40*M40 -> 16196902 | O40: =IF(OR(I40="OPEN",I40="PARTIALLY PAID"),(G40-L40)*M40,0) -> 16196902 | P40: =IF(O40>0,MAX(0,DATE(2025,3,31)-E40),0) -> 0 | Q40: =IF(H40="","",H40-E40) | R40: =IF(O40=0,"Not open",IF(P40=0,"Not yet due",IF(P40<=30,"1-30",IF(P40<=60,"31-60",IF(P40<=90,"61-90","90+"))))) -> Not yet due
...

Sheet customers
A1: customer_id | B1: customer_name | C1: country | D1: billing_currency | E1: industry | F1: credit_rating | G1: credit_limit_inr | H1: onboarding_date | I1: limit_flag | J1: payment_terms_days
A2: C0001 | B2: Alpine Construction Industries Ltd | C2: India | D2: INR | E2: Construction | F2: BBB | G2: 7500000 | H2: 44020 | J2: 45
A3: C0002 | B3: Sahyadri Textiles Enterprises Pvt Ltd | C3: India | D3: INR | E3: Packaging | F3: BBB | G3: 28950000 | H3: 42009 | J3: 45
A4: C0003 | B4: Danube Industrial Plastics LLP | C4: India | D4: INR | E4: Packaging | F4: B | G4: 15500000 | H4: 42585 | J4: 45
A5: C0004 | B5: Aarav FMCG Plastics LLP | C5: India | D5: INR | E5: FMCG | F5: BBB | G5: 114250000 | H5: 43164 | J5: 45
A6: C0005 | B6: Everest Agri Products Enterprises Pvt Ltd | C6: India | D6: INR | E6: Industrial | F6: BBB | G6: 63550000 | H6: 44670 | J6: 30
A7: C0006 | B7: Danube Packaging GmbH | C7: Germany | D7: EUR | E7: Industrial | F7: A | G7: 98150000 | H7: 42648 | J7: 30
A8: C0007 | B8: Titan Packaging Inc | C8: USA | D8: USD | E8: Auto Components | F8: BB | G8: 42200000 | H8: 43958 | J8: 30
A9: C0008 | B9: Meridian Agri Products Industries Ltd | C9: India | D9: INR | E9: Electricals | F9: A | G9: 27050000 | H9: 43126 | J9: 90
A10: C0009 | B10: Gateway Healthcare Industries Ltd | C10: India | D10: INR | E10: Textiles | F10: AA | G10: 126700000 | H10: 44719 | J10: 60
A11: C0010 | B11: Titan Industrial Co. Ltd | C11: Vietnam | D11: USD | E11: Textiles | F11: BBB | G11: 43800000 | H11: 45021 | J11: 60
A12: C0011 | B12: Titan Electricals Industries Ltd | C12: India | D12: INR | E12: Packaging | F12: BB | G12: 35350000 | H12: 42324 | J12: 45
A13: C0012 | B13: Harbor Industrial SAS | C13: France | D13: EUR | E13: Auto Components | F13: Unrated | G13: 9500000 | H13: 43659 | J13: 60
... A19: C0018 | B19: Lakeshore Electricals Polymers Pvt Ltd | C19: India | D19: INR | E19: Electricals | F19: BBB | G19: 24800000 | H19: 44426 | J19: 30
A20: C0019 | B20: Redwood Textiles GmbH | C20: Germany | D20: EUR | E20: Consumer Goods | F20: BB | G20: 0 | H20: 43269 | I20: Invalid limit | J20: 90
A21: C0020 | B21: Maple Construction Co. Ltd | C21: Vietnam | D21: USD | E21: Agri Products | F21: CCC | G21: 10200000 | H21: 42469 | J21: 90
A22: C0021 | B22: Zephyr FMCG Inc | C22: USA | D22: USD | E22: Healthcare | F22: A | G22: 27950000 | H22: 43246 | J22: 90
A23: C0022 | B23: Harbor Textiles Industries Ltd | C23: India | D23: INR | E23: Auto Components | F23: BBB | G23: 27450000 | H23: 43333 | J23: 30
A24: C0023 | B24: Udaya Auto Components Industries Ltd | C24: India | D24: INR | E24: Auto Components | F24: CCC | G24: 5850000 | H24: 44865 | J24: 45
A25: C0024 | B25: Xenon Textiles Industries Ltd | C25: India | D25: INR | E25: Electricals | F25: AA | G25: 47650000 | H25: 43980 | J25: 30
A26: C0025 | B26: Lotus FMCG Pte Ltd | C26: Singapore | D26: USD | E26: Healthcare | F26: BB | G26: 64550000 | H26: 44447 | J26: 45
A27: C0026 | B27: Pacific Consumer Goods Plastics LLP | C27: India | D27: INR | E27: Healthcare | F27: BBB | G27: 39350000 | H27: 42390 | J27: 30
A28: C0027 | B28: Udaya Agri Products Ltd | C28: Bangladesh | D28: USD | E28: FMCG | F28: BBB | G28: 9250000 | H28: 42067 | J28: 60
A29: C0028 | B29: Rajdhani Consumer Goods Enterprises Pvt Ltd | C29: India | D29: INR | E29: Consumer Goods | F29: Unrated | G29: 58400000 | H29: 42189 | J29: 30
A30: C0029 | B30: Quartz Healthcare Polymers Pvt Ltd | C30: India | D30: INR | E30: Textiles | F30: Unrated | G30: 50800000 | H30: 43923 | J30: 90
A31: C0030 | B31: Cedar FMCG Industries Ltd | C31: India | D31: INR | E31: Agri Products | F31: BBB | G31: 42850000 | H31: 42401 | J31: 60
A32: C0031 | B32: Sahyadri Electricals Plastics LLP | C32: India | D32: INR | E32: Textiles | F32: AAA | G32: 94450000 | H32: 42134 | J32: 90
... A48: C0047 | B48: Aarav Industrial General Trading LLC | C48: UAE | D48: USD | E48: Agri Products | F48: AA | G48: 88650000 | H48: 44796 | J48: 90
A49: C0048 | B49: Zephyr Construction Industries Ltd | C49: India | D49: INR | E49: Healthcare | F49: B | G49: 0 | H49: 42249 | I49: Invalid limit | J49: 45
A50: C0049 | B50: Meridian Packaging Enterprises Pvt Ltd | C50: India | D50: INR | E50: Industrial | F50: AAA | G50: 218650000 | H50: 44130 | J50: 30
A51: C0050 | B51: Aarav Agri Products Plastics LLP | C51: India | D51: INR | E51: Auto Components | F51: A | G51: 202900000 | H51: 43674 | J51: 60
A52: C0051 | B52: Harbor Auto Components S.p.A. | C52: Italy | D52: EUR | E52: Textiles | F52: A | G52: 48950000 | H52: 44873 | J52: 60
A53: C0052 | B53: Unity Construction Plastics LLP | C53: India | D53: INR | E53: Packaging | F53: Unrated | G53: 102450000 | H53: 44012 | J53: 30
A54: C0053 | B54: Everest Healthcare GmbH | C54: Germany | D54: EUR | E54: Construction | F54: A | G54: 43150000 | H54: 44514 | J54: 60
A55: C0054 | B55: Ganga Auto Components GmbH | C55: Germany | D55: EUR | E55: FMCG | F55: A | G55: 95300000 | H55: 44259 | J55: 60
A56: C0055 | B56: Indus Industrial Industries Ltd | C56: India | D56: INR | E56: FMCG | F56: A | G56: 60000000 | H56: 43166 | J56: 45
A57: C0056 | B57: Yamuna Healthcare Industries Ltd | C57: India | D57: INR | E57: Construction | F57: BBB | G57: 52350000 | H57: 42477 | J57: 60
A58: C0057 | B58: Yamuna Industrial Industries Ltd | C58: India | D58: INR | E58: Industrial | F58: AA | G58: -5000000 | H58: 44474 | I58: Invalid limit | J58: 30
A59: C0058 | B59: Vista Textiles Enterprises Pvt Ltd | C59: India | D59: INR | E59: Packaging | F59: BBB | G59: 29800000 | H59: 44688 | J59: 30
A60: C0059 | B60: Harbor Packaging Polymers Pvt Ltd | C60: India | D60: INR | E60: Consumer Goods | F60: A | G60: 86550000 | H60: 43377 | J60: 30
...

Sheet purchases
A1: purchase_id | B1: purchase_date | C1: bu_id | D1: currency | E1: quantity | F1: unit | G1: total_amount | H1: hedged_flag | I1: hedge_price | J1: material | K1: unit_price | L1: payment_date | M1: total_amount_INR | N1: days_to_pay_supplier
A2: PUR00005 | B2: 45019 | C2: BU03 | D2: USD | E2: 2153 | F2: bbl-eq | G2: 186083.79 | H2: N | J2: Crude-linked feedstock | K2: 86.43 | L2: 45049 | M2: =G2*IF(D2="INR",1,INDEX('rates'!$B$2:$B$522,MATCH(B2,'rates'!$A$2:$A$522,1))) -> 15303531 | N2: =IF(L2="","",L2-B2) -> 30
A3: PUR00012 | B3: 45023 | C3: BU04 | D3: INR | E3: 49318 | F3: kg | G3: 4419879.2 | H3: N | J3: Additives & packaging | K3: 89.62 | L3: 45053 | M3: =G3*IF(D3="INR",1,INDEX('rates'!$B$2:$B$522,MATCH(B3,'rates'!$A$2:$A$522,1))) -> 4419879.2 | N3: =IF(L3="","",L3-B3) -> 30
A4: PUR00013 | B4: 45023 | C4: BU04 | D4: USD | E4: 383 | F4: bbl-eq | G4: 32344.35 | H4: Y | I4: 86.03 | J4: Crude-linked feedstock | K4: 84.45 | L4: 45053 | M4: =G4*IF(D4="INR",1,INDEX('rates'!$B$2:$B$522,MATCH(B4,'rates'!$A$2:$A$522,1))) -> 2647385 | N4: =IF(L4="","",L4-B4) -> 30
A5: PUR00016 | B5: 45023 | C5: BU03 | D5: USD | E5: 1349 | F5: bbl-eq | G5: 115056.21 | H5: Y | I5: 86.03 | J5: Crude-linked feedstock | K5: 85.29 | L5: 45053 | M5: =G5*IF(D5="INR",1,INDEX('rates'!$B$2:$B$522,MATCH(B5,'rates'!$A$2:$A$522,1))) -> 9417350.8 | N5: =IF(L5="","",L5-B5) -> 30
A6: PUR00022 | B6: 45028 | C6: BU02 | D6: INR | E6: 29927 | F6: kg | G6: 2663802.3 | H6: N | J6: Additives & packaging | K6: 89.01 | L6: 45058 | M6: =G6*IF(D6="INR",1,INDEX('rates'!$B$2:$B$522,MATCH(B6,'rates'!$A$2:$A$522,1))) -> 2663802.3 | N6: =IF(L6="","",L6-B6) -> 30
A7: PUR00025 | B7: 45030 | C7: BU01 | D7: USD | E7: 429 | F7: bbl-eq | G7: 38361.18 | H7: N | J7: Crude-linked feedstock | K7: 89.42 | L7: 45060 | M7: =G7*IF(D7="INR",1,INDEX('rates'!$B$2:$B$522,MATCH(B7,'rates'!$A$2:$A$522,1))) -> 3141013.4 | N7: =IF(L7="","",L7-B7) -> 30
A8: PUR00029 | B8: 45033 | C8: BU05 | D8: USD | E8: 921 | F8: bbl-eq | G8: 79150.74 | H8: N | J8: Crude-linked feedstock | K8: 85.94 | L8: 45063 | M8: =G8*IF(D8="INR",1,INDEX('rates'!$B$2:$B$522,MATCH(B8,'rates'!$A$2:$A$522,1))) -> 6488777.7 | N8: =IF(L8="","",L8-B8) -> 30
A9: PUR00002 | B9: 45019 | C9: BU01 | D9: USD | E9: 1019 | F9: bbl-eq | G9: 88163.88 | H9: Y | I9: 86.03 | J9: Crude-linked feedstock | K9: 86.52 | L9: 45064 | M9: =G9*IF(D9="INR",1,INDEX('rates'!$B$2:$B$522,MATCH(B9,'rates'!$A$2:$A$522,1))) -> 7250597.5 | N9: =IF(L9="","",L9-B9) -> 45
A10: PUR00031 | B10: 45034 | C10: BU04 | D10: USD | E10: 1868 | F10: bbl-eq | G10: 160591.96 | H10: N | J10: Crude-linked feedstock | K10: 85.97 | L10: 45064 | M10: =G10*IF(D10="INR",1,INDEX('rates'!$B$2:$B$522,MATCH(B10,'rates'!$A$2:$A$522,1))) -> 13181388 | N10: =IF(L10="","",L10-B10) -> 30
A11: PUR00006 | B11: 45020 | C11: BU02 | D11: USD | E11: 1819 | F11: bbl-eq | G11: 152832.38 | H11: N | J11: Crude-linked feedstock | K11: 84.02 | L11: 45065 | M11: =G11*IF(D11="INR",1,INDEX('rates'!$B$2:$B$522,MATCH(B11,'rates'!$A$2:$A$522,1))) -> 12582690 | N11: =IF(L11="","",L11-B11) -> 45
A12: PUR00034 | B12: 45035 | C12: BU02 | D12: USD | E12: 689 | F12: bbl-eq | G12: 58220.5 | H12: Y | J12: Crude-linked feedstock | K12: 84.5 | L12: 45065 | M12: =G12*IF(D12="INR",1,INDEX('rates'!$B$2:$B$522,MATCH(B12,'rates'!$A$2:$A$522,1))) -> 4784560.7 | N12: =IF(L12="","",L12-B12) -> 30
A13: PUR00036 | B13: 45035 | C13: BU03 | D13: USD | E13: 1073 | F13: bbl-eq | G13: 90475.36 | H13: Y | I13: 86.03 | J13: Crude-linked feedstock | K13: 84.32 | L13: 45065 | M13: =G13*IF(D13="INR",1,INDEX('rates'!$B$2:$B$522,MATCH(B13,'rates'!$A$2:$A$522,1))) -> 7435265.1 | N13: =IF(L13="","",L13-B13) -> 30
A14: PUR00008 | B14: 45021 | C14: BU05 | D14: USD | E14: 877 | F14: bbl-eq | G14: 76035.9 | H14: Y | I14: 86.03 | J14: Crude-linked feedstock | K14: 86.7 | L14: 45066 | M14: =G14*IF(D14="INR",1,INDEX('rates'!$B$2:$B$522,MATCH(B14,'rates'!$A$2:$A$522,1))) -> 6226579.9 | N14: =IF(L14="","",L14-B14) -> 45
A15: PUR00009 | B15: 45022 | C15: BU04 | D15: USD | E15: 457 | F15: bbl-eq | G15: 38991.24 | H15: Y | I15: 86.03 | J15: Crude-linked feedstock | K15: 85.32 | L15: 45067 | M15: =G15*IF(D15="INR",1,INDEX('rates'!$B$2:$B$522,MATCH(B15,'rates'!$A$2:$A$522,1))) -> 3191822.9 | N15: =IF(L15="","",L15-B15) -> 45
A16: PUR00041 | B16: 45037 | C16: BU03 | D16: USD | E16: 1361 | F16: bbl-eq | G16: 112704.41 | H16: Y | I16: 86.03 | J16: Crude-linked feedstock | K16: 82.81 | L16: 45067 | M16: =G16*IF(D16="INR",1,INDEX('rates'!$B$2:$B$522,MATCH(B16,'rates'!$A$2:$A$522,1))) -> 9248523.9 | N16: =IF(L16="","",L16-B16) -> 30
A17: PUR00042 | B17: 45037 | C17: BU05 | D17: USD | E17: 676 | F17: bbl-eq | G17: 55911.96 | H17: N | J17: Crude-linked feedstock | K17: 82.71 | L17: 45067 | M17: =G17*IF(D17="INR",1,INDEX('rates'!$B$2:$B$522,MATCH(B17,'rates'!$A$2:$A$522,1))) -> 4588135.4 | N17: =IF(L17="","",L17-B17) -> 30
A18: PUR00046 | B18: 45037 | C18: BU03 | D18: USD | E18: 421 | F18: bbl-eq | G18: 34623.04 | H18: Y | I18: 86.03 | J18: Crude-linked feedstock | K18: 82.24 | L18: 45067 | M18: =G18*IF(D18="INR",1,INDEX('rates'!$B$2:$B$522,MATCH(B18,'rates'!$A$2:$A$522,1))) -> 2841166.7 | N18: =IF(L18="","",L18-B18) -> 30
A19: PUR00010 | B19: 45023 | C19: BU02 | D19: INR | E19: 59370 | F19: kg | G19: 5079697.2 | H19: N | J19: Additives & packaging | K19: 85.56 | L19: 45068 | M19: =G19*IF(D19="INR",1,INDEX('rates'!$B$2:$B$522,MATCH(B19,'rates'!$A$2:$A$522,1))) -> 5079697.2 | N19: =IF(L19="","",L19-B19) -> 45
A20: PUR00014 | B20: 45023 | C20: BU01 | D20: USD | E20: 917 | F20: bbl-eq | G20: 79513.07 | H20: N | J20: Crude-linked feedstock | K20: 86.71 | L20: 45068 | M20: =G20*IF(D20="INR",1,INDEX('rates'!$B$2:$B$522,MATCH(B20,'rates'!$A$2:$A$522,1))) -> 6508144.8 | N20: =IF(L20="","",L20-B20) -> 45
A21: PUR00047 | B21: 45040 | C21: BU05 | D21: USD | E21: 637 | F21: bbl-eq | G21: 53304.16 | H21: Y | I21: 86.03 | J21: Crude-linked feedstock | K21: 83.68 | L21: 45070 | M21: =G21*IF(D21="INR",1,INDEX('rates'!$B$2:$B$522,MATCH(B21,'rates'!$A$2:$A$522,1))) -> 4365610.7 | N21: =IF(L21="","",L21-B21) -> 30
A22: PUR00049 | B22: 45040 | C22: BU04 | D22: USD | E22: 712 | F22: bbl-eq | G22: 59644.24 | H22: N | J22: Crude-linked feedstock | K22: 83.77 | L22: 45070 | M22: =G22*IF(D22="INR",1,INDEX('rates'!$B$2:$B$522,MATCH(B22,'rates'!$A$2:$A$522,1))) -> 4884863.3 | N22: =IF(L22="","",L22-B22) -> 30
A23: PUR00050 | B23: 45042 | C23: BU02 | D23: USD | E23: 1545 | F23: bbl-eq | G23: 123182.85 | H23: N | J23: Crude-linked feedstock | K23: 79.73 | L23: 45072 | M23: =G23*IF(D23="INR",1,INDEX('rates'!$B$2:$B$522,MATCH(B23,'rates'!$A$2:$A$522,1))) -> 10068966 | N23: =IF(L23="","",L23-B23) -> 30
A24: PUR00051 | B24: 45042 | C24: BU04 | D24: USD | E24: 1129 | F24: bbl-eq | G24: 88457.15 | H24: N | J24: Crude-linked feedstock | K24: 78.35 | L24: 45072 | M24: =G24*IF(D24="INR",1,INDEX('rates'!$B$2:$B$522,MATCH(B24,'rates'!$A$2:$A$522,1))) -> 7230487.4 | N24: =IF(L24="","",L24-B24) -> 30
A25: PUR00021 | B25: 45028 | C25: BU02 | D25: USD | E25: 565 | F25: bbl-eq | G25: 50177.65 | H25: N | J25: Crude-linked feedstock | K25: 88.81 | L25: 45073 | M25: =G25*IF(D25="INR",1,INDEX('rates'!$B$2:$B$522,MATCH(B25,'rates'!$A$2:$A$522,1))) -> 4113563.7 | N25: =IF(L25="","",L25-B25) -> 45
A26: PUR00055 | B26: 45043 | C26: BU04 | D26: INR | E26: 125862 | F26: kg | G26: 10359701 | H26: N | J26: Additives & packaging | K26: 82.31 | L26: 45073 | M26: =G26*IF(D26="INR",1,INDEX('rates'!$B$2:$B$522,MATCH(B26,'rates'!$A$2:$A$522,1))) -> 10359701 | N26: =IF(L26="","",L26-B26) -> 30
A27: PUR00023 | B27: 45029 | C27: BU01 | D27: INR | E27: 34331 | F27: kg | G27: 3524420.5 | H27: N | J27: Additives & packaging | K27: 102.66 | L27: 45074 | M27: =G27*IF(D27="INR",1,INDEX('rates'!$B$2:$B$522,MATCH(B27,'rates'!$A$2:$A$522,1))) -> 3524420.5 | N27: =IF(L27="","",L27-B27) -> 45
A28: PUR00028 | B28: 45033 | C28: BU01 | D28: USD | E28: 1990 | F28: bbl-eq | G28: 167279.4 | H28: Y | I28: 86.03 | J28: Crude-linked feedstock | K28: 84.06 | L28: 45078 | M28: =G28*IF(D28="INR",1,INDEX('rates'!$B$2:$B$522,MATCH(B28,'rates'!$A$2:$A$522,1))) -> 13713565 | N28: =IF(L28="","",L28-B28) -> 45
A29: PUR00030 | B29: 45033 | C29: BU02 | D29: USD | E29: 371 | F29: bbl-eq | G29: 31449.67 | H29: Y | I29: 86.03 | J29: Crude-linked feedstock | K29: 84.77 | L29: 45078 | M29: =G29*IF(D29="INR",1,INDEX('rates'!$B$2:$B$522,MATCH(B29,'rates'!$A$2:$A$522,1))) -> 2578243.9 | N29: =IF(L29="","",L29-B29) -> 45
A30: PUR00001 | B30: 45019 | C30: BU03 | D30: USD | E30: 1609 | F30: bbl-eq | G30: 136604.1 | H30: N | J30: Crude-linked feedstock | K30: 84.9 | L30: 45079 | M30: =G30*IF(D30="INR",1,INDEX('rates'!$B$2:$B$522,MATCH(B30,'rates'!$A$2:$A$522,1))) -> 11234321 | N30: =IF(L30="","",L30-B30) -> 60
A31: PUR00003 | B31: 45019 | C31: BU04 | D31: USD | E31: 921 | F31: bbl-eq | G31: 78809.97 | H31: Y | I31: 86.03 | J31: Crude-linked feedstock | K31: 85.57 | L31: 45079 | M31: =G31*IF(D31="INR",1,INDEX('rates'!$B$2:$B$522,MATCH(B31,'rates'!$A$2:$A$522,1))) -> 6481331.9 | N31: =IF(L31="","",L31-B31) -> 60
A32: PUR00004 | B32: 45019 | C32: BU05 | D32: USD | E32: 1527 | F32: bbl-eq | G32: 130024.05 | H32: Y | I32: 86.03 | J32: Crude-linked feedstock | K32: 85.15 | L32: 45079 | M32: =G32*IF(D32="INR",1,INDEX('rates'!$B$2:$B$522,MATCH(B32,'rates'!$A$2:$A$522,1))) -> 10693178 | N32: =IF(L32="","",L32-B32) -> 60
A33: PUR00032 | B33: 45034 | C33: BU04 | D33: INR | E33: 36226 | F33: kg | G33: 3095874 | H33: N | J33: Additives & packaging | K33: 85.46 | L33: 45079 | M33: =G33*IF(D33="INR",1,INDEX('rates'!$B$2:$B$522,MATCH(B33,'rates'!$A$2:$A$522,1))) -> 3095874 | N33: =IF(L33="","",L33-B33) -> 45
A34: PUR00064 | B34: 45049 | C34: BU04 | D34: USD | E34: 2326 | F34: bbl-eq | G34: 168053.5 | H34: Y | I34: 86.03 | J34: Crude-linked feedstock | K34: 72.25 | L34: 45079 | M34: =G34*IF(D34="INR",1,INDEX('rates'!$B$2:$B$522,MATCH(B34,'rates'!$A$2:$A$522,1))) -> 13751818 | N34: =IF(L34="","",L34-B34) -> 30
A35: PUR00033 | B35: 45035 | C35: BU02 | D35: INR | E35: 109772 | F35: kg | G35: 9027649.3 | H35: N | J35: Additives & packaging | K35: 82.24 | L35: 45080 | M35: =G35*IF(D35="INR",1,INDEX('rates'!$B$2:$B$522,MATCH(B35,'rates'!$A$2:$A$522,1))) -> 9027649.3 | N35: =IF(L35="","",L35-B35) -> 45
A36: PUR00007 | B36: 45021 | C36: BU03 | D36: INR | E36: 45536 | F36: kg | G36: 3685228.5 | H36: N | J36: Additives & packaging | K36: 80.93 | L36: 45081 | M36: =G36*IF(D36="INR",1,INDEX('rates'!$B$2:$B$522,MATCH(B36,'rates'!$A$2:$A$522,1))) -> 3685228.5 | N36: =IF(L36="","",L36-B36) -> 60
A37: PUR00067 | B37: 45051 | C37: BU05 | D37: USD | E37: 695 | F37: bbl-eq | G37: 53049.35 | H37: Y | I37: 86.03 | J37: Crude-linked feedstock | K37: 76.33 | L37: 45081 | M37: =G37*IF(D37="INR",1,INDEX('rates'!$B$2:$B$522,MATCH(B37,'rates'!$A$2:$A$522,1))) -> 4339967.3 | N37: =IF(L37="","",L37-B37) -> 30
A38: PUR00037 | B38: 45037 | C38: BU02 | D38: USD | E38: 2428 | F38: bbl-eq | G38: 201014.12 | H38: N | J38: Crude-linked feedstock | K38: 82.79 | L38: 45082 | M38: =G38*IF(D38="INR",1,INDEX('rates'!$B$2:$B$522,MATCH(B38,'rates'!$A$2:$A$522,1))) -> 16495219 | N38: =IF(L38="","",L38-B38) -> 45
A39: PUR00039 | B39: 45037 | C39: BU05 | D39: INR | E39: 107990 | F39: kg | G39: 9223425.9 | H39: N | J39: Additives & packaging | K39: 85.41 | L39: 45082 | M39: =G39*IF(D39="INR",1,INDEX('rates'!$B$2:$B$522,MATCH(B39,'rates'!$A$2:$A$522,1))) -> 9223425.9 | N39: =IF(L39="","",L39-B39) -> 45
A40: PUR00043 | B40: 45037 | C40: BU01 | D40: USD | E40: 1796 | F40: bbl-eq | G40: 147505.48 | H40: N | J40: Crude-linked feedstock | K40: 82.13 | L40: 45082 | M40: =G40*IF(D40="INR",1,INDEX('rates'!$B$2:$B$522,MATCH(B40,'rates'!$A$2:$A$522,1))) -> 12104300 | N40: =IF(L40="","",L40-B40) -> 45
...

Sheet market_prices
A1: price_id | B1: date | C1: asset | D1: asset_class | E1: price | F1: unit | G1: source | H1: carried_forward
A2: MP00522 | B2: 45019 | C2: EUR/INR | D2: FX | E2: 89.5676 | F2: INR per EUR | G2: Derived: FRED DEXUSEU x DEXINUS (Federal Reserve H.10) | H2: No
A3: MP00523 | B3: 45020 | C3: EUR/INR | D3: FX | E3: 90.1596 | F3: INR per EUR | G3: Derived: FRED DEXUSEU x DEXINUS (Federal Reserve H.10) | H3: No
A4: MP00524 | B4: 45021 | C4: EUR/INR | D4: FX | E4: 89.4075 | F4: INR per EUR | G4: Derived: FRED DEXUSEU x DEXINUS (Federal Reserve H.10) | H4: No
A5: MP00525 | B5: 45022 | C5: EUR/INR | D5: FX | E5: 89.4484 | F5: INR per EUR | G5: Derived: FRED DEXUSEU x DEXINUS (Federal Reserve H.10) | H5: No
A6: MP00526 | B6: 45023 | C6: EUR/INR | D6: FX | E6: 89.3229 | F6: INR per EUR | G6: Derived: FRED DEXUSEU x DEXINUS (Federal Reserve H.10) | H6: No
A7: MP00527 | B7: 45026 | C7: EUR/INR | D7: FX | E7: 88.8988 | F7: INR per EUR | G7: Derived: FRED DEXUSEU x DEXINUS (Federal Reserve H.10) | H7: No
A8: MP00528 | B8: 45027 | C8: EUR/INR | D8: FX | E8: 89.4728 | F8: INR per EUR | G8: Derived: FRED DEXUSEU x DEXINUS (Federal Reserve H.10) | H8: No
A9: MP00529 | B9: 45028 | C9: EUR/INR | D9: FX | E9: 90.0714 | F9: INR per EUR | G9: Derived: FRED DEXUSEU x DEXINUS (Federal Reserve H.10) | H9: No
A10: MP00530 | B10: 45029 | C10: EUR/INR | D10: FX | E10: 90.2559 | F10: INR per EUR | G10: Derived: FRED DEXUSEU x DEXINUS (Federal Reserve H.10) | H10: No
A11: MP00531 | B11: 45030 | C11: EUR/INR | D11: FX | E11: 89.9042 | F11: INR per EUR | G11: Derived: FRED DEXUSEU x DEXINUS (Federal Reserve H.10) | H11: No
A12: MP00532 | B12: 45033 | C12: EUR/INR | D12: FX | E12: 89.4812 | F12: INR per EUR | G12: Derived: FRED DEXUSEU x DEXINUS (Federal Reserve H.10) | H12: No
A13: MP00533 | B13: 45034 | C13: EUR/INR | D13: FX | E13: 89.9433 | F13: INR per EUR | G13: Derived: FRED DEXUSEU x DEXINUS (Federal Reserve H.10) | H13: No
... A1564: MP01563 | B1564: 45747 | C1564: WTI Crude | D1564: Commodity | E1564: 71.87 | F1564: USD per barrel | G1564: FRED DCOILWTICO (US EIA) | H1564: No

Sheet rates
A1: date | B1: USD/INR | C1: EUR/INR | D1: WTI Crude | E1: USD/INR return | F1: EUR/INR return | G1: WTI return
A2: 45019 | B2: =SUMIFS(market_prices!$E:$E,market_prices!$B:$B,$A2,market_prices!$C:$C,B$1) -> 82.24 | C2: =SUMIFS(market_prices!$E:$E,market_prices!$B:$B,$A2,market_prices!$C:$C,C$1) -> 89.5676 | D2: =SUMIFS(market_prices!$E:$E,market_prices!$B:$B,$A2,market_prices!$C:$C,D$1) -> 80.4
A3: 45020 | B3: =SUMIFS(market_prices!$E:$E,market_prices!$B:$B,$A3,market_prices!$C:$C,B$1) -> 82.33 | C3: =SUMIFS(market_prices!$E:$E,market_prices!$B:$B,$A3,market_prices!$C:$C,C$1) -> 90.1596 | D3: =SUMIFS(market_prices!$E:$E,market_prices!$B:$B,$A3,market_prices!$C:$C,D$1) -> 80.7 | E3: =B3/B2-1 -> 0.001094358 | F3: =rates[[#This Row],[EUR/INR]]/C2-1 -> 0.0066095329 | G3: =rates[[#This Row],[WTI Crude]]/D2-1 -> 0.0037313433
A4: 45021 | B4: =SUMIFS(market_prices!$E:$E,market_prices!$B:$B,$A4,market_prices!$C:$C,B$1) -> 81.89 | C4: =SUMIFS(market_prices!$E:$E,market_prices!$B:$B,$A4,market_prices!$C:$C,C$1) -> 89.4075 | D4: =SUMIFS(market_prices!$E:$E,market_prices!$B:$B,$A4,market_prices!$C:$C,D$1) -> 80.69 | E4: =B4/B3-1 -> -0.0053443459 | F4: =rates[[#This Row],[EUR/INR]]/C3-1 -> -0.0083418737 | G4: =rates[[#This Row],[WTI Crude]]/D3-1 -> -0.00012391574
A5: 45022 | B5: =SUMIFS(market_prices!$E:$E,market_prices!$B:$B,$A5,market_prices!$C:$C,B$1) -> 81.86 | C5: =SUMIFS(market_prices!$E:$E,market_prices!$B:$B,$A5,market_prices!$C:$C,C$1) -> 89.4484 | D5: =SUMIFS(market_prices!$E:$E,market_prices!$B:$B,$A5,market_prices!$C:$C,D$1) -> 80.7 | E5: =B5/B4-1 -> -0.0003663451 | F5: =rates[[#This Row],[EUR/INR]]/C4-1 -> 0.00045745603 | G5: =rates[[#This Row],[WTI Crude]]/D4-1 -> 0.00012393109
A6: 45023 | B6: =SUMIFS(market_prices!$E:$E,market_prices!$B:$B,$A6,market_prices!$C:$C,B$1) -> 81.85 | C6: =SUMIFS(market_prices!$E:$E,market_prices!$B:$B,$A6,market_prices!$C:$C,C$1) -> 89.3229 | D6: =SUMIFS(market_prices!$E:$E,market_prices!$B:$B,$A6,market_prices!$C:$C,D$1) -> 80.7 | E6: =B6/B5-1 -> -0.00012215978 | F6: =rates[[#This Row],[EUR/INR]]/C5-1 -> -0.0014030435 | G6: =rates[[#This Row],[WTI Crude]]/D5-1 -> 0
A7: 45026 | B7: =SUMIFS(market_prices!$E:$E,market_prices!$B:$B,$A7,market_prices!$C:$C,B$1) -> 82.01 | C7: =SUMIFS(market_prices!$E:$E,market_prices!$B:$B,$A7,market_prices!$C:$C,C$1) -> 88.8988 | D7: =SUMIFS(market_prices!$E:$E,market_prices!$B:$B,$A7,market_prices!$C:$C,D$1) -> 79.79 | E7: =B7/B6-1 -> 0.0019547954 | F7: =rates[[#This Row],[EUR/INR]]/C6-1 -> -0.0047479426 | G7: =rates[[#This Row],[WTI Crude]]/D6-1 -> -0.011276332
A8: 45027 | B8: =SUMIFS(market_prices!$E:$E,market_prices!$B:$B,$A8,market_prices!$C:$C,B$1) -> 82.04 | C8: =SUMIFS(market_prices!$E:$E,market_prices!$B:$B,$A8,market_prices!$C:$C,C$1) -> 89.4728 | D8: =SUMIFS(market_prices!$E:$E,market_prices!$B:$B,$A8,market_prices!$C:$C,D$1) -> 81.54 | E8: =B8/B7-1 -> 0.00036580905 | F8: =rates[[#This Row],[EUR/INR]]/C7-1 -> 0.0064567801 | G8: =rates[[#This Row],[WTI Crude]]/D7-1 -> 0.021932573
A9: 45028 | B9: =SUMIFS(market_prices!$E:$E,market_prices!$B:$B,$A9,market_prices!$C:$C,B$1) -> 81.98 | C9: =SUMIFS(market_prices!$E:$E,market_prices!$B:$B,$A9,market_prices!$C:$C,C$1) -> 90.0714 | D9: =SUMIFS(market_prices!$E:$E,market_prices!$B:$B,$A9,market_prices!$C:$C,D$1) -> 83.26 | E9: =B9/B8-1 -> -0.00073135056 | F9: =rates[[#This Row],[EUR/INR]]/C8-1 -> 0.0066903014 | G9: =rates[[#This Row],[WTI Crude]]/D8-1 -> 0.021093942
A10: 45029 | B10: =SUMIFS(market_prices!$E:$E,market_prices!$B:$B,$A10,market_prices!$C:$C,B$1) -> 81.65 | C10: =SUMIFS(market_prices!$E:$E,market_prices!$B:$B,$A10,market_prices!$C:$C,C$1) -> 90.2559 | D10: =SUMIFS(market_prices!$E:$E,market_prices!$B:$B,$A10,market_prices!$C:$C,D$1) -> 82.16 | E10: =B10/B9-1 -> -0.004025372 | F10: =rates[[#This Row],[EUR/INR]]/C9-1 -> 0.002048375 | G10: =rates[[#This Row],[WTI Crude]]/D9-1 -> -0.013211626
A11: 45030 | B11: =SUMIFS(market_prices!$E:$E,market_prices!$B:$B,$A11,market_prices!$C:$C,B$1) -> 81.88 | C11: =SUMIFS(market_prices!$E:$E,market_prices!$B:$B,$A11,market_prices!$C:$C,C$1) -> 89.9042 | D11: =SUMIFS(market_prices!$E:$E,market_prices!$B:$B,$A11,market_prices!$C:$C,D$1) -> 82.58 | E11: =B11/B10-1 -> 0.0028169014 | F11: =rates[[#This Row],[EUR/INR]]/C10-1 -> -0.0038966982 | G11: =rates[[#This Row],[WTI Crude]]/D10-1 -> 0.0051119766
A12: 45033 | B12: =SUMIFS(market_prices!$E:$E,market_prices!$B:$B,$A12,market_prices!$C:$C,B$1) -> 81.98 | C12: =SUMIFS(market_prices!$E:$E,market_prices!$B:$B,$A12,market_prices!$C:$C,C$1) -> 89.4812 | D12: =SUMIFS(market_prices!$E:$E,market_prices!$B:$B,$A12,market_prices!$C:$C,D$1) -> 80.93 | E12: =B12/B11-1 -> 0.0012212995 | F12: =rates[[#This Row],[EUR/INR]]/C11-1 -> -0.0047050082 | G12: =rates[[#This Row],[WTI Crude]]/D11-1 -> -0.019980625
A13: 45034 | B13: =SUMIFS(market_prices!$E:$E,market_prices!$B:$B,$A13,market_prices!$C:$C,B$1) -> 82.08 | C13: =SUMIFS(market_prices!$E:$E,market_prices!$B:$B,$A13,market_prices!$C:$C,C$1) -> 89.9433 | D13: =SUMIFS(market_prices!$E:$E,market_prices!$B:$B,$A13,market_prices!$C:$C,D$1) -> 80.85 | E13: =B13/B12-1 -> 0.0012198097 | F13: =rates[[#This Row],[EUR/INR]]/C12-1 -> 0.0051642133 | G13: =rates[[#This Row],[WTI Crude]]/D12-1 -> -0.00098850859
A14: 45035 | B14: =SUMIFS(market_prices!$E:$E,market_prices!$B:$B,$A14,market_prices!$C:$C,B$1) -> 82.18 | C14: =SUMIFS(market_prices!$E:$E,market_prices!$B:$B,$A14,market_prices!$C:$C,C$1) -> 90.0118 | D14: =SUMIFS(market_prices!$E:$E,market_prices!$B:$B,$A14,market_prices!$C:$C,D$1) -> 79.18 | E14: =B14/B13-1 -> 0.0012183236 | F14: =rates[[#This Row],[EUR/INR]]/C13-1 -> 0.00076159091 | G14: =rates[[#This Row],[WTI Crude]]/D13-1 -> -0.020655535
... A522: 45747 | B522: =SUMIFS(market_prices!$E:$E,market_prices!$B:$B,$A522,market_prices!$C:$C,B$1) -> 85.43 | C522: =SUMIFS(market_prices!$E:$E,market_prices!$B:$B,$A522,market_prices!$C:$C,C$1) -> 92.2302 | D522: =SUMIFS(market_prices!$E:$E,market_prices!$B:$B,$A522,market_prices!$C:$C,D$1) -> 71.87 | E522: =B522/B521-1 -> -0.00093556309 | F522: =rates[[#This Row],[EUR/INR]]/C521-1 -> -0.0037040998 | G522: =rates[[#This Row],[WTI Crude]]/D521-1 -> 0.030542013

Sheet market_risk
B2: Metric | C2: USD/INR | D2: EUR/INR | E2: WTI Crude
B3: Daily volatility | C3: =_xlfn.STDEV.S('rates'!E3:E522) -> 0.0015458476 | D3: =_xlfn.STDEV.S('rates'!F3:F522) -> 0.0040790224 | E3: =_xlfn.STDEV.S('rates'!G3:G522) -> 0.018573567
B4: Annualised volatility | C4: =C3*SQRT(252) -> 0.024539569 | D4: =D3*SQRT(252) -> 0.064752473 | E4: =E3*SQRT(252) -> 0.29484623
B5: 1-day 95% VaR, worst fall | C5: =-_xlfn.PERCENTILE.INC('rates'!E3:E522,0.05) -> 0.0023700944 | D5: =-_xlfn.PERCENTILE.INC('rates'!F3:F522,0.05) -> 0.0059949849 | E5: =-_xlfn.PERCENTILE.INC('rates'!G3:G522,0.05) -> 0.031999705
B6: 1-day 95% VaR, worst rise | C6: =_xlfn.PERCENTILE.INC('rates'!E3:E522,0.95) -> 0.002319722 | D6: =_xlfn.PERCENTILE.INC('rates'!F3:F522,0.95) -> 0.0066767601 | E6: =_xlfn.PERCENTILE.INC('rates'!G3:G522,0.95) -> 0.029101812

Sheet working_capital
B2: Business Units | C2: Avg Receivables | D2: Revenue | E2: Avg inventory | F2: Purchases | G2: DSO | H2: DIO | I2: DPO | J2: CCC
B3: BU01 | C3: =AVERAGEIFS(treasury_monthly!$I:$I,treasury_monthly!$B:$B,$B3) -> 8.5298908e+08 | D3: =SUMIFS(invoices!$N:$N,invoices!$C:$C,$B3) -> 8.7421426e+09 | E3: =AVERAGEIFS(treasury_monthly!$H:$H,treasury_monthly!$B:$B,$B3) -> 2.6892938e+08 | F3: =SUMIFS(purchases!$M:$M,purchases!$C:$C,$B3) -> 3.019613e+09 | G3: =C3/D3*$C$8 -> 71.325194 | H3: =E3/F3*$C$8 -> 65.103499 | I3: =AVERAGEIFS(purchases!$N:$N,purchases!$C:$C,$B3) -> 44.481481 | J3: =G3+H3-I3 -> 91.947211
B4: BU02 | C4: =AVERAGEIFS(treasury_monthly!$I:$I,treasury_monthly!$B:$B,$B4) -> 5.1153696e+08 | D4: =SUMIFS(invoices!$N:$N,invoices!$C:$C,$B4) -> 4.6203727e+09 | E4: =AVERAGEIFS(treasury_monthly!$H:$H,treasury_monthly!$B:$B,$B4) -> 2.3320824e+08 | F4: =SUMIFS(purchases!$M:$M,purchases!$C:$C,$B4) -> 2.5845374e+09 | G4: =C4/D4*$C$8 -> 80.931463 | H4: =E4/F4*$C$8 -> 65.959665 | I4: =AVERAGEIFS(purchases!$N:$N,purchases!$C:$C,$B4) -> 45.079576 | J4: =G4+H4-I4 -> 101.81155
B5: BU03 | C5: =AVERAGEIFS(treasury_monthly!$I:$I,treasury_monthly!$B:$B,$B5) -> 3.2588516e+08 | D5: =SUMIFS(invoices!$N:$N,invoices!$C:$C,$B5) -> 3.1526427e+09 | E5: =AVERAGEIFS(treasury_monthly!$H:$H,treasury_monthly!$B:$B,$B5) -> 1.3118656e+08 | F5: =SUMIFS(purchases!$M:$M,purchases!$C:$C,$B5) -> 1.4889959e+09 | G5: =C5/D5*$C$8 -> 75.562656 | H5: =E5/F5*$C$8 -> 64.404054 | I5: =AVERAGEIFS(purchases!$N:$N,purchases!$C:$C,$B5) -> 44.475 | J5: =G5+H5-I5 -> 95.491709
B6: BU04 | C6: =AVERAGEIFS(treasury_monthly!$I:$I,treasury_monthly!$B:$B,$B6) -> 3.915878e+08 | D6: =SUMIFS(invoices!$N:$N,invoices!$C:$C,$B6) -> 4.3250676e+09 | E6: =AVERAGEIFS(treasury_monthly!$H:$H,treasury_monthly!$B:$B,$B6) -> 1.4440113e+08 | F6: =SUMIFS(purchases!$M:$M,purchases!$C:$C,$B6) -> 1.5354433e+09 | G6: =C6/D6*$C$8 -> 66.184094 | H6: =E6/F6*$C$8 -> 68.747071 | I6: =AVERAGEIFS(purchases!$N:$N,purchases!$C:$C,$B6) -> 43.392857 | J6: =G6+H6-I6 -> 91.538307
B7: BU05 | C7: =AVERAGEIFS(treasury_monthly!$I:$I,treasury_monthly!$B:$B,$B7) -> 3.4486197e+08 | D7: =SUMIFS(invoices!$N:$N,invoices!$C:$C,$B7) -> 2.9997631e+09 | E7: =AVERAGEIFS(treasury_monthly!$H:$H,treasury_monthly!$B:$B,$B7) -> 1.6941832e+08 | F7: =SUMIFS(purchases!$M:$M,purchases!$C:$C,$B7) -> 1.9365737e+09 | G7: =C7/D7*$C$8 -> 84.038003 | H7: =E7/F7*$C$8 -> 63.950468 | I7: =AVERAGEIFS(purchases!$N:$N,purchases!$C:$C,$B7) -> 44.532872 | J7: =G7+H7-I7 -> 103.4556
B8: Days in period | C8: =DATE(2025,3,31)-DATE(2023,4,1)+1 -> 731

Sheet aging_pivot
B2: Aging Group | C2: Count of invoice | D2: Open Balance in Cr.
B3: 1-30 | C3: 47 | D3: 33.451257
B4: 31-60 | C4: 15 | D4: 9.1154764
B5: 61-90 | C5: 11 | D5: 6.4302573
B6: 90+ | C6: 112 | D6: 43.607401
B7: Not yet due | C7: 231 | D7: 194.7867
B8: Grand Total | C8: 416 | D8: 287.39109
